Workbook

Sheet Обработка исходного
A1: Класс материала | C1: Марка стали или сплава | E1: Сортамент | F1: Параметр | G1: Температура, К (°С)
G2: 20 | H2: 50 | I2: 100 | J2: 150 | K2: 200 | L2: 250 | M2: 300 | N2: 350 | O2: 400 | P2: 450 | Q2: 500 | R2: 550 | S2: 600
A3: Сталь углеродистая | B3: =IF(NOT(ISBLANK(A3)),A3,IF(NOT(ISBLANK(E3)),INDEX(B:B,ROW(B3)-4),"")) -> Сталь углеродистая | C3: Ст3сп5 | D3: =IF(NOT(ISBLANK(C3)),C3,IF(NOT(ISBLANK(E3)),INDEX(D:D,ROW(D3)-4),"")) -> Ст3сп5 | E3: Горячекатаная сортовая фасонная и листовая сталь толщиной до 20 мм | F3: =CHOOSE(MOD(ROW(F3)-ROW($F$3),4)+1, "Предел прочности, МПа", "Предел текучести, МПа", "Относительное удлинение пятикратного образца при растяжении, %", "Относительное сужение поперечного сечения образца при растяжении, %") -> Предел прочности, МПа | G3: 373 | H3: 363 | I3: 353 | J3: 353 | K3: 343 | L3: 323 | M3: 284 | N3: - | O3: - | P3: - | Q3: - | R3: - | S3: -
B4: =IF(NOT(ISBLANK(A4)),A4,IF(NOT(ISBLANK(E4)),INDEX(B:B,ROW(B4)-4),"")) | D4: =IF(NOT(ISBLANK(C4)),C4,IF(NOT(ISBLANK(E4)),INDEX(D:D,ROW(D4)-4),"")) | F4: =CHOOSE(MOD(ROW(F4)-ROW($F$3),4)+1, "Предел прочности, МПа", "Предел текучести, МПа", "Относительное удлинение пятикратного образца при растяжении, %", "Относительное сужение поперечного сечения образца при растяжении, %") -> Предел текучести, МПа | G4: 245 | H4: 235 | I4: 235 | J4: 235 | K4: 235 | L4: 206 | M4: 186 | N4: - | O4: - | P4: - | Q4: - | R4: - | S4: -
B5: =IF(NOT(ISBLANK(A5)),A5,IF(NOT(ISBLANK(E5)),INDEX(B:B,ROW(B5)-4),"")) | D5: =IF(NOT(ISBLANK(C5)),C5,IF(NOT(ISBLANK(E5)),INDEX(D:D,ROW(D5)-4),"")) | F5: =CHOOSE(MOD(ROW(F5)-ROW($F$3),4)+1, "Предел прочности, МПа", "Предел текучести, МПа", "Относительное удлинение пятикратного образца при растяжении, %", "Относительное сужение поперечного сечения образца при растяжении, %") -> Относительное удлинение пятикратного образца при растяжении, % | G5: 26 | H5: 24 | I5: 22 | J5: 20 | K5: 20 | L5: 20 | M5: 20 | N5: - | O5: - | P5: - | Q5: - | R5: - | S5: -
B6: =IF(NOT(ISBLANK(A6)),A6,IF(NOT(ISBLANK(E6)),INDEX(B:B,ROW(B6)-4),"")) | D6: =IF(NOT(ISBLANK(C6)),C6,IF(NOT(ISBLANK(E6)),INDEX(D:D,ROW(D6)-4),"")) | F6: =CHOOSE(MOD(ROW(F6)-ROW($F$3),4)+1, "Предел прочности, МПа", "Предел текучести, МПа", "Относительное удлинение пятикратного образца при растяжении, %", "Относительное сужение поперечного сечения образца при растяжении, %") -> Относительное сужение поперечного сечения образца при растяжении, % | G6: 50 | H6: 49 | I6: 49 | J6: 48 | K6: 47 | L6: 47 | M6: 48 | N6: - | O6: - | P6: - | Q6: - | R6: - | S6: -
B7: =IF(NOT(ISBLANK(A7)),A7,IF(NOT(ISBLANK(E7)),INDEX(B:B,ROW(B7)-4),"")) -> Сталь углеродистая | D7: =IF(NOT(ISBLANK(C7)),C7,IF(NOT(ISBLANK(E7)),INDEX(D:D,ROW(D7)-4),"")) -> Ст3сп5 | E7: Горячекатаная сортовая фасонная и листовая сталь толщиной от 20 до 100 мм | F7: =CHOOSE(MOD(ROW(F7)-ROW($F$3),4)+1, "Предел прочности, МПа", "Предел текучести, МПа", "Относительное удлинение пятикратного образца при растяжении, %", "Относительное сужение поперечного сечения образца при растяжении, %") -> Предел прочности, МПа | G7: 373 | H7: 363 | I7: 353 | J7: 353 | K7: 343 | L7: 323 | M7: 284 | N7: - | O7: - | P7: - | Q7: - | R7: - | S7: -
B8: =IF(NOT(ISBLANK(A8)),A8,IF(NOT(ISBLANK(E8)),INDEX(B:B,ROW(B8)-4),"")) | D8: =IF(NOT(ISBLANK(C8)),C8,IF(NOT(ISBLANK(E8)),INDEX(D:D,ROW(D8)-4),"")) | F8: =CHOOSE(MOD(ROW(F8)-ROW($F$3),4)+1, "Предел прочности, МПа", "Предел текучести, МПа", "Относительное удлинение пятикратного образца при растяжении, %", "Относительное сужение поперечного сечения образца при растяжении, %") -> Предел текучести, МПа | G8: 206 | H8: 196 | I8: 196 | J8: 196 | K8: 196 | L8: 177 | M8: 157 | N8: - | O8: - | P8: - | Q8: - | R8: - | S8: -
B9: =IF(NOT(ISBLANK(A9)),A9,IF(NOT(ISBLANK(E9)),INDEX(B:B,ROW(B9)-4),"")) | D9: =IF(NOT(ISBLANK(C9)),C9,IF(NOT(ISBLANK(E9)),INDEX(D:D,ROW(D9)-4),"")) | F9: =CHOOSE(MOD(ROW(F9)-ROW($F$3),4)+1, "Предел прочности, МПа", "Предел текучести, МПа", "Относительное удлинение пятикратного образца при растяжении, %", "Относительное сужение поперечного сечения образца при растяжении, %") -> Относительное удлинение пятикратного образца при растяжении, % | G9: 23 | H9: 21 | I9: 19 | J9: 18 | K9: 18 | L9: 18 | M9: 18 | N9: - | O9: - | P9: - | Q9: - | R9: - | S9: -
B10: =IF(NOT(ISBLANK(A10)),A10,IF(NOT(ISBLANK(E10)),INDEX(B:B,ROW(B10)-4),"")) | D10: =IF(NOT(ISBLANK(C10)),C10,IF(NOT(ISBLANK(E10)),INDEX(D:D,ROW(D10)-4),"")) | F10: =CHOOSE(MOD(ROW(F10)-ROW($F$3),4)+1, "Предел прочности, МПа", "Предел текучести, МПа", "Относительное удлинение пятикратного образца при растяжении, %", "Относительное сужение поперечного сечения образца при растяжении, %") -> Относительное сужение поперечного сечения образца при растяжении, % | G10: 50 | H10: 49 | I10: 49 | J10: 48 | K10: 47 | L10: 47 | M10: 48 | N10: - | O10: - | P10: - | Q10: - | R10: - | S10: -
B11: =IF(NOT(ISBLANK(A11)),A11,IF(NOT(ISBLANK(E11)),INDEX(B:B,ROW(B11)-4),"")) -> Сталь углеродистая | D11: =IF(NOT(ISBLANK(C11)),C11,IF(NOT(ISBLANK(E11)),INDEX(D:D,ROW(D11)-4),"")) -> Ст3сп5 | E11: Горячекатаная сортовая фасонная и листовая сталь толщиной более 100 мм | F11: =CHOOSE(MOD(ROW(F11)-ROW($F$3),4)+1, "Предел прочности, МПа", "Предел текучести, МПа", "Относительное удлинение пятикратного образца при растяжении, %", "Относительное сужение поперечного сечения образца при растяжении, %") -> Предел прочности, МПа | G11: 373 | H11: 363 | I11: 353 | J11: 353 | K11: 343 | L11: 323 | M11: 284 | N11: - | O11: - | P11: - | Q11: - | R11: - | S11: -
B12: =IF(NOT(ISBLANK(A12)),A12,IF(NOT(ISBLANK(E12)),INDEX(B:B,ROW(B12)-4),"")) | D12: =IF(NOT(ISBLANK(C12)),C12,IF(NOT(ISBLANK(E12)),INDEX(D:D,ROW(D12)-4),"")) | F12: =CHOOSE(MOD(ROW(F12)-ROW($F$3),4)+1, "Предел прочности, МПа", "Предел текучести, МПа", "Относительное удлинение пятикратного образца при растяжении, %", "Относительное сужение поперечного сечения образца при растяжении, %") -> Предел текучести, МПа | G12: 206 | H12: 196 | I12: 196 | J12: 196 | K12: 196 | L12: 177 | M12: 157 | N12: - | O12: - | P12: - | Q12: - | R12: - | S12: -
B13: =IF(NOT(ISBLANK(A13)),A13,IF(NOT(ISBLANK(E13)),INDEX(B:B,ROW(B13)-4),"")) | D13: =IF(NOT(ISBLANK(C13)),C13,IF(NOT(ISBLANK(E13)),INDEX(D:D,ROW(D13)-4),"")) | F13: =CHOOSE(MOD(ROW(F13)-ROW($F$3),4)+1, "Предел прочности, МПа", "Предел текучести, МПа", "Относительное удлинение пятикратного образца при растяжении, %", "Относительное сужение поперечного сечения образца при растяжении, %") -> Относительное удлинение пятикратного образца при растяжении, % | G13: 23 | H13: 21 | I13: 19 | J13: 18 | K13: 18 | L13: 18 | M13: 18 | N13: - | O13: - | P13: - | Q13: - | R13: - | S13: -
B14: =IF(NOT(ISBLANK(A14)),A14,IF(NOT(ISBLANK(E14)),INDEX(B:B,ROW(B14)-4),"")) | D14: =IF(NOT(ISBLANK(C14)),C14,IF(NOT(ISBLANK(E14)),INDEX(D:D,ROW(D14)-4),"")) | F14: =CHOOSE(MOD(ROW(F14)-ROW($F$3),4)+1, "Предел прочности, МПа", "Предел текучести, МПа", "Относительное удлинение пятикратного образца при растяжении, %", "Относительное сужение поперечного сечения образца при растяжении, %") -> Относительное сужение поперечного сечения образца при растяжении, % | G14: 50 | H14: 49 | I14: 49 | J14: 48 | K14: 47 | L14: 47 | M14: 48 | N14: - | O14: - | P14: - | Q14: - | R14: - | S14: -
B15: =IF(NOT(ISBLANK(A15)),A15,IF(NOT(ISBLANK(E15)),INDEX(B:B,ROW(B15)-4),"")) -> Сталь углеродистая | D15: =IF(NOT(ISBLANK(C15)),C15,IF(NOT(ISBLANK(E15)),INDEX(D:D,ROW(D15)-4),"")) -> Ст3сп5 | E15: Трубы | F15: =CHOOSE(MOD(ROW(F15)-ROW($F$3),4)+1, "Предел прочности, МПа", "Предел текучести, МПа", "Относительное удлинение пятикратного образца при растяжении, %", "Относительное сужение поперечного сечения образца при растяжении, %") -> Предел прочности, МПа | G15: 373 | H15: 363 | I15: 353 | J15: 343 | K15: 343 | L15: 323 | M15: 324 | N15: - | O15: - | P15: - | Q15: - | R15: - | S15: -
B16: =IF(NOT(ISBLANK(A16)),A16,IF(NOT(ISBLANK(E16)),INDEX(B:B,ROW(B16)-4),"")) | D16: =IF(NOT(ISBLANK(C16)),C16,IF(NOT(ISBLANK(E16)),INDEX(D:D,ROW(D16)-4),"")) | F16: =CHOOSE(MOD(ROW(F16)-ROW($F$3),4)+1, "Предел прочности, МПа", "Предел текучести, МПа", "Относительное удлинение пятикратного образца при растяжении, %", "Относительное сужение поперечного сечения образца при растяжении, %") -> Предел текучести, МПа | G16: 206 | H16: 196 | I16: 196 | J16: 196 | K16: 196 | L16: 177 | M16: 157 | N16: - | O16: - | P16: - | Q16: - | R16: - | S16: -
B17: =IF(NOT(ISBLANK(A17)),A17,IF(NOT(ISBLANK(E17)),INDEX(B:B,ROW(B17)-4),"")) | D17: =IF(NOT(ISBLANK(C17)),C17,IF(NOT(ISBLANK(E17)),INDEX(D:D,ROW(D17)-4),"")) | F17: =CHOOSE(MOD(ROW(F17)-ROW($F$3),4)+1, "Предел прочности, МПа", "Предел текучести, МПа", "Относительное удлинение пятикратного образца при растяжении, %", "Относительное сужение поперечного сечения образца при растяжении, %") -> Относительное удлинение пятикратного образца при растяжении, % | G17: 23 | H17: 21 | I17: 19 | J17: 18 | K17: 18 | L17: 18 | M17: 18 | N17: - | O17: - | P17: - | Q17: - | R17: - | S17: -
B18: =IF(NOT(ISBLANK(A18)),A18,IF(NOT(ISBLANK(E18)),INDEX(B:B,ROW(B18)-4),"")) | D18: =IF(NOT(ISBLANK(C18)),C18,IF(NOT(ISBLANK(E18)),INDEX(D:D,ROW(D18)-4),"")) | F18: =CHOOSE(MOD(ROW(F18)-ROW($F$3),4)+1, "Предел прочности, МПа", "Предел текучести, МПа", "Относительное удлинение пятикратного образца при растяжении, %", "Относительное сужение поперечного сечения образца при растяжении, %") -> Относительное сужение поперечного сечения образца при растяжении, % | G18: 50 | H18: 49 | I18: 49 | J18: 48 | K18: 47 | L18: 47 | M18: 48 | N18: - | O18: - | P18: - | Q18: - | R18: - | S18: -
B19: =IF(NOT(ISBLANK(A19)),A19,IF(NOT(ISBLANK(E19)),INDEX(B:B,ROW(B19)-4),"")) -> Сталь углеродистая | D19: =IF(NOT(ISBLANK(C19)),C19,IF(NOT(ISBLANK(E19)),INDEX(D:D,ROW(D19)-4),"")) -> Ст3сп5 | E19: Поковки диаметром или толщиной до 300 мм, КП175* | F19: =CHOOSE(MOD(ROW(F19)-ROW($F$3),4)+1, "Предел прочности, МПа", "Предел текучести, МПа", "Относительное удлинение пятикратного образца при растяжении, %", "Относительное сужение поперечного сечения образца при растяжении, %") -> Предел прочности, МПа | G19: 355 | H19: 343 | I19: 333 | J19: 333 | K19: 314 | L19: 304 | M19: 275 | N19: - | O19: - | P19: - | Q19: - | R19: - | S19: -
B20: =IF(NOT(ISBLANK(A20)),A20,IF(NOT(ISBLANK(E20)),INDEX(B:B,ROW(B20)-4),"")) | D20: =IF(NOT(ISBLANK(C20)),C20,IF(NOT(ISBLANK(E20)),INDEX(D:D,ROW(D20)-4),"")) | F20: =CHOOSE(MOD(ROW(F20)-ROW($F$3),4)+1, "Предел прочности, МПа", "Предел текучести, МПа", "Относительное удлинение пятикратного образца при растяжении, %", "Относительное сужение поперечного сечения образца при растяжении, %") -> Предел текучести, МПа | G20: 175 | H20: 167 | I20: 167 | J20: 167 | K20: 157 | L20: 147 | M20: 137 | N20: - | O20: - | P20: - | Q20: - | R20: - | S20: -
B21: =IF(NOT(ISBLANK(A21)),A21,IF(NOT(ISBLANK(E21)),INDEX(B:B,ROW(B21)-4),"")) | D21: =IF(NOT(ISBLANK(C21)),C21,IF(NOT(ISBLANK(E21)),INDEX(D:D,ROW(D21)-4),"")) | F21: =CHOOSE(MOD(ROW(F21)-ROW($F$3),4)+1, "Предел прочности, МПа", "Предел текучести, МПа", "Относительное удлинение пятикратного образца при растяжении, %", "Относительное сужение поперечного сечения образца при растяжении, %") -> Относительное удлинение пятикратного образца при растяжении, % | G21: 24 | H21: 22 | I21: 20 | J21: 18 | K21: 17 | L21: 17 | M21: 17 | N21: - | O21: - | P21: - | Q21: - | R21: - | S21: -
B22: =IF(NOT(ISBLANK(A22)),A22,IF(NOT(ISBLANK(E22)),INDEX(B:B,ROW(B22)-4),"")) | D22: =IF(NOT(ISBLANK(C22)),C22,IF(NOT(ISBLANK(E22)),INDEX(D:D,ROW(D22)-4),"")) | F22: =CHOOSE(MOD(ROW(F22)-ROW($F$3),4)+1, "Предел прочности, МПа", "Предел текучести, МПа", "Относительное удлинение пятикратного образца при растяжении, %", "Относительное сужение поперечного сечения образца при растяжении, %") -> Относительное сужение поперечного сечения образца при растяжении, % | G22: 50 | H22: 47 | I22: 44 | J22: 41 | K22: 40 | L22: 40 | M22: 40 | N22: - | O22: - | P22: - | Q22: - | R22: - | S22: -
B23: =IF(NOT(ISBLANK(A23)),A23,IF(NOT(ISBLANK(E23)),INDEX(B:B,ROW(B23)-4),"")) -> Сталь углеродистая | D23: =IF(NOT(ISBLANK(C23)),C23,IF(NOT(ISBLANK(E23)),INDEX(D:D,ROW(D23)-4),"")) -> Ст3сп5 | E23: Поковки диаметром или толщиной до 300 мм, КП195* | F23: =CHOOSE(MOD(ROW(F23)-ROW($F$3),4)+1, "Предел прочности, МПа", "Предел текучести, МПа", "Относительное удлинение пятикратного образца при растяжении, %", "Относительное сужение поперечного сечения образца при растяжении, %") -> Предел прочности, МПа | G23: 390 | H23: 390 | I23: 373 | J23: 373 | K23: 363 | L23: 333 | M23: 304 | N23: - | O23: - | P23: - | Q23: - | R23: - | S23: -
B24: =IF(NOT(ISBLANK(A24)),A24,IF(NOT(ISBLANK(E24)),INDEX(B:B,ROW(B24)-4),"")) | D24: =IF(NOT(ISBLANK(C24)),C24,IF(NOT(ISBLANK(E24)),INDEX(D:D,ROW(D24)-4),"")) | F24: =CHOOSE(MOD(ROW(F24)-ROW($F$3),4)+1, "Предел прочности, МПа", "Предел текучести, МПа", "Относительное удлинение пятикратного образца при растяжении, %", "Относительное сужение поперечного сечения образца при растяжении, %") -> Предел текучести, МПа | G24: 195 | H24: 195 | I24: 195 | J24: 195 | K24: 177 | L24: 167 | M24: 147 | N24: - | O24: - | P24: - | Q24: - | R24: - | S24: -
B25: =IF(NOT(ISBLANK(A25)),A25,IF(NOT(ISBLANK(E25)),INDEX(B:B,ROW(B25)-4),"")) | D25: =IF(NOT(ISBLANK(C25)),C25,IF(NOT(ISBLANK(E25)),INDEX(D:D,ROW(D25)-4),"")) | F25: =CHOOSE(MOD(ROW(F25)-ROW($F$3),4)+1, "Предел прочности, МПа", "Предел текучести, МПа", "Относительное удлинение пятикратного образца при растяжении, %", "Относительное сужение поперечного сечения образца при растяжении, %") -> Относительное удлинение пятикратного образца при растяжении, % | G25: 23 | H25: 21 | I25: 20 | J25: 18 | K25: 18 | L25: 18 | M25: 18 | N25: - | O25: - | P25: - | Q25: - | R25: - | S25: -
B26: =IF(NOT(ISBLANK(A26)),A26,IF(NOT(ISBLANK(E26)),INDEX(B:B,ROW(B26)-4),"")) | D26: =IF(NOT(ISBLANK(C26)),C26,IF(NOT(ISBLANK(E26)),INDEX(D:D,ROW(D26)-4),"")) | F26: =CHOOSE(MOD(ROW(F26)-ROW($F$3),4)+1, "Предел прочности, МПа", "Предел текучести, МПа", "Относительное удлинение пятикратного образца при растяжении, %", "Относительное сужение поперечного сечения образца при растяжении, %") -> Относительное сужение поперечного сечения образца при растяжении, % | G26: 50 | H26: 47 | I26: 44 | J26: 41 | K26: 40 | L26: 40 | M26: 40 | N26: - | O26: - | P26: - | Q26: - | R26: - | S26: -
B27: =IF(NOT(ISBLANK(A27)),A27,IF(NOT(ISBLANK(E27)),INDEX(B:B,ROW(B27)-4),"")) -> Сталь углеродистая | D27: =IF(NOT(ISBLANK(C27)),C27,IF(NOT(ISBLANK(E27)),INDEX(D:D,ROW(D27)-4),"")) -> Ст3сп5 | E27: Поковки диаметром или толщиной до 50 мм, КП215* | F27: =CHOOSE(MOD(ROW(F27)-ROW($F$3),4)+1, "Предел прочности, МПа", "Предел текучести, МПа", "Относительное удлинение пятикратного образца при растяжении, %", "Относительное сужение поперечного сечения образца при растяжении, %") -> Предел прочности, МПа | G27: 420 | H27: 422 | I27: 402 | J27: 402 | K27: 392 | L27: 373 | M27: 333 | N27: - | O27: - | P27: - | Q27: - | R27: - | S27: -
B28: =IF(NOT(ISBLANK(A28)),A28,IF(NOT(ISBLANK(E28)),INDEX(B:B,ROW(B28)-4),"")) | D28: =IF(NOT(ISBLANK(C28)),C28,IF(NOT(ISBLANK(E28)),INDEX(D:D,ROW(D28)-4),"")) | F28: =CHOOSE(MOD(ROW(F28)-ROW($F$3),4)+1, "Предел прочности, МПа", "Предел текучести, МПа", "Относительное удлинение пятикратного образца при растяжении, %", "Относительное сужение поперечного сечения образца при растяжении, %") -> Предел текучести, МПа | G28: 215 | H28: 206 | I28: 206 | J28: 206 | K28: 196 | L28: 196 | M28: 167 | N28: - | O28: - | P28: - | Q28: - | R28: - | S28: -
B29: =IF(NOT(ISBLANK(A29)),A29,IF(NOT(ISBLANK(E29)),INDEX(B:B,ROW(B29)-4),"")) | D29: =IF(NOT(ISBLANK(C29)),C29,IF(NOT(ISBLANK(E29)),INDEX(D:D,ROW(D29)-4),"")) | F29: =CHOOSE(MOD(ROW(F29)-ROW($F$3),4)+1, "Предел прочности, МПа", "Предел текучести, МПа", "Относительное удлинение пятикратного образца при растяжении, %", "Относительное сужение поперечного сечения образца при растяжении, %") -> Относительное удлинение пятикратного образца при растяжении, % | G29: 23 | H29: 21 | I29: 20 | J29: 18 | K29: 18 | L29: 18 | M29: 18 | N29: - | O29: - | P29: - | Q29: - | R29: - | S29: -
B30: =IF(NOT(ISBLANK(A30)),A30,IF(NOT(ISBLANK(E30)),INDEX(B:B,ROW(B30)-4),"")) | D30: =IF(NOT(ISBLANK(C30)),C30,IF(NOT(ISBLANK(E30)),INDEX(D:D,ROW(D30)-4),"")) | F30: =CHOOSE(MOD(ROW(F30)-ROW($F$3),4)+1, "Предел прочности, МПа", "Предел текучести, МПа", "Относительное удлинение пятикратного образца при растяжении, %", "Относительное сужение поперечного сечения образца при растяжении, %") -> Относительное сужение поперечного сечения образца при растяжении, % | G30: 50 | H30: 47 | I30: 44 | J30: 41 | K30: 40 | L30: 40 | M30: 40 | N30: - | O30: - | P30: - | Q30: - | R30: - | S30: -
A31: Сталь углеродистая | B31: =IF(NOT(ISBLANK(A31)),A31,IF(NOT(ISBLANK(E31)),INDEX(B:B,ROW(B31)-4),"")) -> Сталь углеродистая | C31: 10 | D31: =IF(NOT(ISBLANK(C31)),C31,IF(NOT(ISBLANK(E31)),INDEX(D:D,ROW(D31)-4),"")) -> 10 | E31: Трубы холодно- и теплодеформированные бесшовные | F31: =CHOOSE(MOD(ROW(F31)-ROW($F$3),4)+1, "Предел прочности, МПа", "Предел текучести, МПа", "Относительное удлинение пятикратного образца при растяжении, %", "Относительное сужение поперечного сечения образца при растяжении, %") -> Предел прочности, МПа | G31: 343 | H31: 333 | I31: 333 | J31: 333 | K31: 333 | L31: 323 | M31: 314 | N31: 294 | O31: - | P31: - | Q31: - | R31: - | S31: -
B32: =IF(NOT(ISBLANK(A32)),A32,IF(NOT(ISBLANK(E32)),INDEX(B:B,ROW(B32)-4),"")) | D32: =IF(NOT(ISBLANK(C32)),C32,IF(NOT(ISBLANK(E32)),INDEX(D:D,ROW(D32)-4),"")) | F32: =CHOOSE(MOD(ROW(F32)-ROW($F$3),4)+1, "Предел прочности, МПа", "Предел текучести, МПа", "Относительное удлинение пятикратного образца при растяжении, %", "Относительное сужение поперечного сечения образца при растяжении, %") -> Предел текучести, МПа | G32: 206 | H32: 196 | I32: 195 | J32: 181 | K32: 176 | L32: 157 | M32: 137 | N32: 118 | O32: - | P32: - | Q32: - | R32: - | S32: -
B33: =IF(NOT(ISBLANK(A33)),A33,IF(NOT(ISBLANK(E33)),INDEX(B:B,ROW(B33)-4),"")) | D33: =IF(NOT(ISBLANK(C33)),C33,IF(NOT(ISBLANK(E33)),INDEX(D:D,ROW(D33)-4),"")) | F33: =CHOOSE(MOD(ROW(F33)-ROW($F$3),4)+1, "Предел прочности, МПа", "Предел текучести, МПа", "Относительное удлинение пятикратного образца при растяжении, %", "Относительное сужение поперечного сечения образца при растяжении, %") -> Относительное удлинение пятикратного образца при растяжении, % | G33: 24 | H33: 20 | I33: 18 | J33: 18 | K33: 19 | L33: 21 | M33: 23 | N33: 24 | O33: - | P33: - | Q33: - | R33: - | S33: -
B34: =IF(NOT(ISBLANK(A34)),A34,IF(NOT(ISBLANK(E34)),INDEX(B:B,ROW(B34)-4),"")) | D34: =IF(NOT(ISBLANK(C34)),C34,IF(NOT(ISBLANK(E34)),INDEX(D:D,ROW(D34)-4),"")) | F34: =CHOOSE(MOD(ROW(F34)-ROW($F$3),4)+1, "Предел прочности, МПа", "Предел текучести, МПа", "Относительное удлинение пятикратного образца при растяжении, %", "Относительное сужение поперечного сечения образца при растяжении, %") -> Относительное сужение поперечного сечения образца при растяжении, % | G34: 50 | H34: 46 | I34: 40 | J34: 40 | K34: 40 | L34: 42 | M34: 44 | N34: 48 | O34: - | P34: - | Q34: - | R34: - | S34: -
B35: =IF(NOT(ISBLANK(A35)),A35,IF(NOT(ISBLANK(E35)),INDEX(B:B,ROW(B35)-4),"")) -> Сталь углеродистая | D35: =IF(NOT(ISBLANK(C35)),C35,IF(NOT(ISBLANK(E35)),INDEX(D:D,ROW(D35)-4),"")) -> 10 | E35: Сортовая горячекатаная и кованая сталь толщиной или диаметром до 80 мм | F35: =CHOOSE(MOD(ROW(F35)-ROW($F$3),4)+1, "Предел прочности, МПа", "Предел текучести, МПа", "Относительное удлинение пятикратного образца при растяжении, %", "Относительное сужение поперечного сечения образца при растяжении, %") -> Предел прочности, МПа | G35: 333 | H35: 333 | I35: 333 | J35: 333 | K35: 333 | L35: 323 | M35: 314 | N35: 294 | O35: - | P35: - | Q35: - | R35: - | S35: -
B36: =IF(NOT(ISBLANK(A36)),A36,IF(NOT(ISBLANK(E36)),INDEX(B:B,ROW(B36)-4),"")) | D36: =IF(NOT(ISBLANK(C36)),C36,IF(NOT(ISBLANK(E36)),INDEX(D:D,ROW(D36)-4),"")) | F36: =CHOOSE(MOD(ROW(F36)-ROW($F$3),4)+1, "Предел прочности, МПа", "Предел текучести, МПа", "Относительное удлинение пятикратного образца при растяжении, %", "Относительное сужение поперечного сечения образца при растяжении, %") -> Предел текучести, МПа | G36: 186 | H36: 186 | I36: 186 | J36: 177 | K36: 177 | L36: 157 | M36: 137 | N36: 118 | O36: - | P36: - | Q36: - | R36: - | S36: -
B37: =IF(NOT(ISBLANK(A37)),A37,IF(NOT(ISBLANK(E37)),INDEX(B:B,ROW(B37)-4),"")) | D37: =IF(NOT(ISBLANK(C37)),C37,IF(NOT(ISBLANK(E37)),INDEX(D:D,ROW(D37)-4),"")) | F37: =CHOOSE(MOD(ROW(F37)-ROW($F$3),4)+1, "Предел прочности, МПа", "Предел текучести, МПа", "Относительное удлинение пятикратного образца при растяжении, %", "Относительное сужение поперечного сечения образца при растяжении, %") -> Относительное удлинение пятикратного образца при растяжении, % | G37: 31 | H37: 28 | I37: 26 | J37: 22 | K37: 25 | L37: 24.5 | M37: 25.5 | N37: 28 | O37: - | P37: - | Q37: - | R37: - | S37: -
B38: =IF(NOT(ISBLANK(A38)),A38,IF(NOT(ISBLANK(E38)),INDEX(B:B,ROW(B38)-4),"")) | D38: =IF(NOT(ISBLANK(C38)),C38,IF(NOT(ISBLANK(E38)),INDEX(D:D,ROW(D38)-4),"")) | F38: =CHOOSE(MOD(ROW(F38)-ROW($F$3),4)+1, "Предел прочности, МПа", "Предел текучести, МПа", "Относительное удлинение пятикратного образца при растяжении, %", "Относительное сужение поперечного сечения образца при растяжении, %") -> Относительное сужение поперечного сечения образца при растяжении, % | G38: 55 | H38: 50 | I38: 50 | J38: 46 | K38: 44 | L38: 44 | M38: 44 | N38: 46 | O38: - | P38: - | Q38: - | R38: - | S38: -
A39: Сталь углеродистая | B39: =IF(NOT(ISBLANK(A39)),A39,IF(NOT(ISBLANK(E39)),INDEX(B:B,ROW(B39)-4),"")) -> Сталь углеродистая | C39: 15 | D39: =IF(NOT(ISBLANK(C39)),C39,IF(NOT(ISBLANK(E39)),INDEX(D:D,ROW(D39)-4),"")) -> 15 | E39: Сортовая горячекатаная сталь толщиной или диаметром до 80 мм | F39: =CHOOSE(MOD(ROW(F39)-ROW($F$3),4)+1, "Предел прочности, МПа", "Предел текучести, МПа", "Относительное удлинение пятикратного образца при растяжении, %", "Относительное сужение поперечного сечения образца при растяжении, %") -> Предел прочности, МПа | G39: 373 | H39: 373 | I39: 363 | J39: 353 | K39: 343 | L39: 333 | M39: 333 | N39: 333 | O39: - | P39: - | Q39: - | R39: - | S39: -
B40: =IF(NOT(ISBLANK(A40)),A40,IF(NOT(ISBLANK(E40)),INDEX(B:B,ROW(B40)-4),"")) | D40: =IF(NOT(ISBLANK(C40)),C40,IF(NOT(ISBLANK(E40)),INDEX(D:D,ROW(D40)-4),"")) | F40: =CHOOSE(MOD(ROW(F40)-ROW($F$3),4)+1, "Предел прочности, МПа", "Предел текучести, МПа", "Относительное удлинение пятикратного образца при растяжении, %", "Относительное сужение поперечного сечения образца при растяжении, %") -> Предел текучести, МПа | G40: 226 | H40: 216 | I40: 216 | J40: 196 | K40: 196 | L40: 196 | M40: 196 | N40: 196 | O40: - | P40: - | Q40: - | R40: - | S40: -
...

Sheet Rm, МПа
A1: Класс материала | B1: Марка стали или сплава | C1: Сортамент | D1: Температура, К (°С)
D2: 20 | E2: 50 | F2: 100 | G2: 150 | H2: 200 | I2: 250 | J2: 300 | K2: 350 | L2: 400 | M2: 450 | N2: 500 | O2: 550 | P2: 600
A3: =INDEX('Обработка исходного'!B:B,ROW($B$3)+4*(ROW($B3)-ROW($B$3))) -> Сталь углеродистая | B3: =INDEX('Обработка исходного'!D:D,ROW($B$3)+4*(ROW($B3)-ROW($B$3))) -> Ст3сп5 | C3: =IF(ISBLANK(INDEX('Обработка исходного'!E:E,ROW($B$3)+4*(ROW($B3)-ROW($B$3)))),"",INDEX('Обработка исходного'!E:E,ROW($B$3)+4*(ROW($B3)-ROW($B$3)))) -> Горячекатаная сортовая фасонная и листовая сталь толщиной до 20 мм | D3: =INDEX('Обработка исходного'!G:G,ROW($B$3)+4*(ROW($B3)-ROW($B$3))) -> 373 | E3: =INDEX('Обработка исходного'!H:H,ROW($B$3)+4*(ROW($B3)-ROW($B$3))) -> 363 | F3: =INDEX('Обработка исходного'!I:I,ROW($B$3)+4*(ROW($B3)-ROW($B$3))) -> 353 | G3: =INDEX('Обработка исходного'!J:J,ROW($B$3)+4*(ROW($B3)-ROW($B$3))) -> 353 | H3: =INDEX('Обработка исходного'!K:K,ROW($B$3)+4*(ROW($B3)-ROW($B$3))) -> 343 | I3: =INDEX('Обработка исходного'!L:L,ROW($B$3)+4*(ROW($B3)-ROW($B$3))) -> 323 | J3: =INDEX('Обработка исходного'!M:M,ROW($B$3)+4*(ROW($B3)-ROW($B$3))) -> 284 | K3: =INDEX('Обработка исходного'!N:N,ROW($B$3)+4*(ROW($B3)-ROW($B$3))) -> - | L3: =INDEX('Обработка исходного'!O:O,ROW($B$3)+4*(ROW($B3)-ROW($B$3))) -> - | M3: =INDEX('Обработка исходного'!P:P,ROW($B$3)+4*(ROW($B3)-ROW($B$3))) -> - | N3: =INDEX('Обработка исходного'!Q:Q,ROW($B$3)+4*(ROW($B3)-ROW($B$3))) -> - | O3: =INDEX('Обработка исходного'!R:R,ROW($B$3)+4*(ROW($B3)-ROW($B$3))) -> - | P3: =INDEX('Обработка исходного'!S:S,ROW($B$3)+4*(ROW($B3)-ROW($B$3))) -> -
A4: =INDEX('Обработка исходного'!B:B,ROW($B$3)+4*(ROW($B4)-ROW($B$3))) -> Сталь углеродистая | B4: =INDEX('Обработка исходного'!D:D,ROW($B$3)+4*(ROW($B4)-ROW($B$3))) -> Ст3сп5 | C4: =IF(ISBLANK(INDEX('Обработка исходного'!E:E,ROW($B$3)+4*(ROW($B4)-ROW($B$3)))),"",INDEX('Обработка исходного'!E:E,ROW($B$3)+4*(ROW($B4)-ROW($B$3)))) -> Горячекатаная сортовая фасонная и листовая сталь толщиной от 20 до 100 мм | D4: =INDEX('Обработка исходного'!G:G,ROW($B$3)+4*(ROW($B4)-ROW($B$3))) -> 373 | E4: =INDEX('Обработка исходного'!H:H,ROW($B$3)+4*(ROW($B4)-ROW($B$3))) -> 363 | F4: =INDEX('Обработка исходного'!I:I,ROW($B$3)+4*(ROW($B4)-ROW($B$3))) -> 353 | G4: =INDEX('Обработка исходного'!J:J,ROW($B$3)+4*(ROW($B4)-ROW($B$3))) -> 353 | H4: =INDEX('Обработка исходного'!K:K,ROW($B$3)+4*(ROW($B4)-ROW($B$3))) -> 343 | I4: =INDEX('Обработка исходного'!L:L,ROW($B$3)+4*(ROW($B4)-ROW($B$3))) -> 323 | J4: =INDEX('Обработка исходного'!M:M,ROW($B$3)+4*(ROW($B4)-ROW($B$3))) -> 284 | K4: =INDEX('Обработка исходного'!N:N,ROW($B$3)+4*(ROW($B4)-ROW($B$3))) -> - | L4: =INDEX('Обработка исходного'!O:O,ROW($B$3)+4*(ROW($B4)-ROW($B$3))) -> - | M4: =INDEX('Обработка исходного'!P:P,ROW($B$3)+4*(ROW($B4)-ROW($B$3))) -> - | N4: =INDEX('Обработка исходного'!Q:Q,ROW($B$3)+4*(ROW($B4)-ROW($B$3))) -> - | O4: =INDEX('Обработка исходного'!R:R,ROW($B$3)+4*(ROW($B4)-ROW($B$3))) -> - | P4: =INDEX('Обработка исходного'!S:S,ROW($B$3)+4*(ROW($B4)-ROW($B$3))) -> -
A5: =INDEX('Обработка исходного'!B:B,ROW($B$3)+4*(ROW($B5)-ROW($B$3))) -> Сталь углеродистая | B5: =INDEX('Обработка исходного'!D:D,ROW($B$3)+4*(ROW($B5)-ROW($B$3))) -> Ст3сп5 | C5: =IF(ISBLANK(INDEX('Обработка исходного'!E:E,ROW($B$3)+4*(ROW($B5)-ROW($B$3)))),"",INDEX('Обработка исходного'!E:E,ROW($B$3)+4*(ROW($B5)-ROW($B$3)))) -> Горячекатаная сортовая фасонная и листовая сталь толщиной более 100 мм | D5: =INDEX('Обработка исходного'!G:G,ROW($B$3)+4*(ROW($B5)-ROW($B$3))) -> 373 | E5: =INDEX('Обработка исходного'!H:H,ROW($B$3)+4*(ROW($B5)-ROW($B$3))) -> 363 | F5: =INDEX('Обработка исходного'!I:I,ROW($B$3)+4*(ROW($B5)-ROW($B$3))) -> 353 | G5: =INDEX('Обработка исходного'!J:J,ROW($B$3)+4*(ROW($B5)-ROW($B$3))) -> 353 | H5: =INDEX('Обработка исходного'!K:K,ROW($B$3)+4*(ROW($B5)-ROW($B$3))) -> 343 | I5: =INDEX('Обработка исходного'!L:L,ROW($B$3)+4*(ROW($B5)-ROW($B$3))) -> 323 | J5: =INDEX('Обработка исходного'!M:M,ROW($B$3)+4*(ROW($B5)-ROW($B$3))) -> 284 | K5: =INDEX('Обработка исходного'!N:N,ROW($B$3)+4*(ROW($B5)-ROW($B$3))) -> - | L5: =INDEX('Обработка исходного'!O:O,ROW($B$3)+4*(ROW($B5)-ROW($B$3))) -> - | M5: =INDEX('Обработка исходного'!P:P,ROW($B$3)+4*(ROW($B5)-ROW($B$3))) -> - | N5: =INDEX('Обработка исходного'!Q:Q,ROW($B$3)+4*(ROW($B5)-ROW($B$3))) -> - | O5: =INDEX('Обработка исходного'!R:R,ROW($B$3)+4*(ROW($B5)-ROW($B$3))) -> - | P5: =INDEX('Обработка исходного'!S:S,ROW($B$3)+4*(ROW($B5)-ROW($B$3))) -> -
A6: =INDEX('Обработка исходного'!B:B,ROW($B$3)+4*(ROW($B6)-ROW($B$3))) -> Сталь углеродистая | B6: =INDEX('Обработка исходного'!D:D,ROW($B$3)+4*(ROW($B6)-ROW($B$3))) -> Ст3сп5 | C6: =IF(ISBLANK(INDEX('Обработка исходного'!E:E,ROW($B$3)+4*(ROW($B6)-ROW($B$3)))),"",INDEX('Обработка исходного'!E:E,ROW($B$3)+4*(ROW($B6)-ROW($B$3)))) -> Трубы | D6: =INDEX('Обработка исходного'!G:G,ROW($B$3)+4*(ROW($B6)-ROW($B$3))) -> 373 | E6: =INDEX('Обработка исходного'!H:H,ROW($B$3)+4*(ROW($B6)-ROW($B$3))) -> 363 | F6: =INDEX('Обработка исходного'!I:I,ROW($B$3)+4*(ROW($B6)-ROW($B$3))) -> 353 | G6: =INDEX('Обработка исходного'!J:J,ROW($B$3)+4*(ROW($B6)-ROW($B$3))) -> 343 | H6: =INDEX('Обработка исходного'!K:K,ROW($B$3)+4*(ROW($B6)-ROW($B$3))) -> 343 | I6: =INDEX('Обработка исходного'!L:L,ROW($B$3)+4*(ROW($B6)-ROW($B$3))) -> 323 | J6: =INDEX('Обработка исходного'!M:M,ROW($B$3)+4*(ROW($B6)-ROW($B$3))) -> 324 | K6: =INDEX('Обработка исходного'!N:N,ROW($B$3)+4*(ROW($B6)-ROW($B$3))) -> - | L6: =INDEX('Обработка исходного'!O:O,ROW($B$3)+4*(ROW($B6)-ROW($B$3))) -> - | M6: =INDEX('Обработка исходного'!P:P,ROW($B$3)+4*(ROW($B6)-ROW($B$3))) -> - | N6: =INDEX('Обработка исходного'!Q:Q,ROW($B$3)+4*(ROW($B6)-ROW($B$3))) -> - | O6: =INDEX('Обработка исходного'!R:R,ROW($B$3)+4*(ROW($B6)-ROW($B$3))) -> - | P6: =INDEX('Обработка исходного'!S:S,ROW($B$3)+4*(ROW($B6)-ROW($B$3))) -> -
A7: =INDEX('Обработка исходного'!B:B,ROW($B$3)+4*(ROW($B7)-ROW($B$3))) -> Сталь углеродистая | B7: =INDEX('Обработка исходного'!D:D,ROW($B$3)+4*(ROW($B7)-ROW($B$3))) -> Ст3сп5 | C7: =IF(ISBLANK(INDEX('Обработка исходного'!E:E,ROW($B$3)+4*(ROW($B7)-ROW($B$3)))),"",INDEX('Обработка исходного'!E:E,ROW($B$3)+4*(ROW($B7)-ROW($B$3)))) -> Поковки диаметром или толщиной до 300 мм, КП175* | D7: =INDEX('Обработка исходного'!G:G,ROW($B$3)+4*(ROW($B7)-ROW($B$3))) -> 355 | E7: =INDEX('Обработка исходного'!H:H,ROW($B$3)+4*(ROW($B7)-ROW($B$3))) -> 343 | F7: =INDEX('Обработка исходного'!I:I,ROW($B$3)+4*(ROW($B7)-ROW($B$3))) -> 333 | G7: =INDEX('Обработка исходного'!J:J,ROW($B$3)+4*(ROW($B7)-ROW($B$3))) -> 333 | H7: =INDEX('Обработка исходного'!K:K,ROW($B$3)+4*(ROW($B7)-ROW($B$3))) -> 314 | I7: =INDEX('Обработка исходного'!L:L,ROW($B$3)+4*(ROW($B7)-ROW($B$3))) -> 304 | J7: =INDEX('Обработка исходного'!M:M,ROW($B$3)+4*(ROW($B7)-ROW($B$3))) -> 275 | K7: =INDEX('Обработка исходного'!N:N,ROW($B$3)+4*(ROW($B7)-ROW($B$3))) -> - | L7: =INDEX('Обработка исходного'!O:O,ROW($B$3)+4*(ROW($B7)-ROW($B$3))) -> - | M7: =INDEX('Обработка исходного'!P:P,ROW($B$3)+4*(ROW($B7)-ROW($B$3))) -> - | N7: =INDEX('Обработка исходного'!Q:Q,ROW($B$3)+4*(ROW($B7)-ROW($B$3))) -> - | O7: =INDEX('Обработка исходного'!R:R,ROW($B$3)+4*(ROW($B7)-ROW($B$3))) -> - | P7: =INDEX('Обработка исходного'!S:S,ROW($B$3)+4*(ROW($B7)-ROW($B$3))) -> -
A8: =INDEX('Обработка исходного'!B:B,ROW($B$3)+4*(ROW($B8)-ROW($B$3))) -> Сталь углеродистая | B8: =INDEX('Обработка исходного'!D:D,ROW($B$3)+4*(ROW($B8)-ROW($B$3))) -> Ст3сп5 | C8: =IF(ISBLANK(INDEX('Обработка исходного'!E:E,ROW($B$3)+4*(ROW($B8)-ROW($B$3)))),"",INDEX('Обработка исходного'!E:E,ROW($B$3)+4*(ROW($B8)-ROW($B$3)))) -> Поковки диаметром или толщиной до 300 мм, КП195* | D8: =INDEX('Обработка исходного'!G:G,ROW($B$3)+4*(ROW($B8)-ROW($B$3))) -> 390 | E8: =INDEX('Обработка исходного'!H:H,ROW($B$3)+4*(ROW($B8)-ROW($B$3))) -> 390 | F8: =INDEX('Обработка исходного'!I:I,ROW($B$3)+4*(ROW($B8)-ROW($B$3))) -> 373 | G8: =INDEX('Обработка исходного'!J:J,ROW($B$3)+4*(ROW($B8)-ROW($B$3))) -> 373 | H8: =INDEX('Обработка исходного'!K:K,ROW($B$3)+4*(ROW($B8)-ROW($B$3))) -> 363 | I8: =INDEX('Обработка исходного'!L:L,ROW($B$3)+4*(ROW($B8)-ROW($B$3))) -> 333 | J8: =INDEX('Обработка исходного'!M:M,ROW($B$3)+4*(ROW($B8)-ROW($B$3))) -> 304 | K8: =INDEX('Обработка исходного'!N:N,ROW($B$3)+4*(ROW($B8)-ROW($B$3))) -> - | L8: =INDEX('Обработка исходного'!O:O,ROW($B$3)+4*(ROW($B8)-ROW($B$3))) -> - | M8: =INDEX('Обработка исходного'!P:P,ROW($B$3)+4*(ROW($B8)-ROW($B$3))) -> - | N8: =INDEX('Обработка исходного'!Q:Q,ROW($B$3)+4*(ROW($B8)-ROW($B$3))) -> - | O8: =INDEX('Обработка исходного'!R:R,ROW($B$3)+4*(ROW($B8)-ROW($B$3))) -> - | P8: =INDEX('Обработка исходного'!S:S,ROW($B$3)+4*(ROW($B8)-ROW($B$3))) -> -
A9: =INDEX('Обработка исходного'!B:B,ROW($B$3)+4*(ROW($B9)-ROW($B$3))) -> Сталь углеродистая | B9: =INDEX('Обработка исходного'!D:D,ROW($B$3)+4*(ROW($B9)-ROW($B$3))) -> Ст3сп5 | C9: =IF(ISBLANK(INDEX('Обработка исходного'!E:E,ROW($B$3)+4*(ROW($B9)-ROW($B$3)))),"",INDEX('Обработка исходного'!E:E,ROW($B$3)+4*(ROW($B9)-ROW($B$3)))) -> Поковки диаметром или толщиной до 50 мм, КП215* | D9: =INDEX('Обработка исходного'!G:G,ROW($B$3)+4*(ROW($B9)-ROW($B$3))) -> 420 | E9: =INDEX('Обработка исходного'!H:H,ROW($B$3)+4*(ROW($B9)-ROW($B$3))) -> 422 | F9: =INDEX('Обработка исходного'!I:I,ROW($B$3)+4*(ROW($B9)-ROW($B$3))) -> 402 | G9: =INDEX('Обработка исходного'!J:J,ROW($B$3)+4*(ROW($B9)-ROW($B$3))) -> 402 | H9: =INDEX('Обработка исходного'!K:K,ROW($B$3)+4*(ROW($B9)-ROW($B$3))) -> 392 | I9: =INDEX('Обработка исходного'!L:L,ROW($B$3)+4*(ROW($B9)-ROW($B$3))) -> 373 | J9: =INDEX('Обработка исходного'!M:M,ROW($B$3)+4*(ROW($B9)-ROW($B$3))) -> 333 | K9: =INDEX('Обработка исходного'!N:N,ROW($B$3)+4*(ROW($B9)-ROW($B$3))) -> - | L9: =INDEX('Обработка исходного'!O:O,ROW($B$3)+4*(ROW($B9)-ROW($B$3))) -> - | M9: =INDEX('Обработка исходного'!P:P,ROW($B$3)+4*(ROW($B9)-ROW($B$3))) -> - | N9: =INDEX('Обработка исходного'!Q:Q,ROW($B$3)+4*(ROW($B9)-ROW($B$3))) -> - | O9: =INDEX('Обработка исходного'!R:R,ROW($B$3)+4*(ROW($B9)-ROW($B$3))) -> - | P9: =INDEX('Обработка исходного'!S:S,ROW($B$3)+4*(ROW($B9)-ROW($B$3))) -> -
A10: =INDEX('Обработка исходного'!B:B,ROW($B$3)+4*(ROW($B10)-ROW($B$3))) -> Сталь углеродистая | B10: =INDEX('Обработка исходного'!D:D,ROW($B$3)+4*(ROW($B10)-ROW($B$3))) -> 10 | C10: =IF(ISBLANK(INDEX('Обработка исходного'!E:E,ROW($B$3)+4*(ROW($B10)-ROW($B$3)))),"",INDEX('Обработка исходного'!E:E,ROW($B$3)+4*(ROW($B10)-ROW($B$3)))) -> Трубы холодно- и теплодеформированные бесшовные | D10: =INDEX('Обработка исходного'!G:G,ROW($B$3)+4*(ROW($B10)-ROW($B$3))) -> 343 | E10: =INDEX('Обработка исходного'!H:H,ROW($B$3)+4*(ROW($B10)-ROW($B$3))) -> 333 | F10: =INDEX('Обработка исходного'!I:I,ROW($B$3)+4*(ROW($B10)-ROW($B$3))) -> 333 | G10: =INDEX('Обработка исходного'!J:J,ROW($B$3)+4*(ROW($B10)-ROW($B$3))) -> 333 | H10: =INDEX('Обработка исходного'!K:K,ROW($B$3)+4*(ROW($B10)-ROW($B$3))) -> 333 | I10: =INDEX('Обработка исходного'!L:L,ROW($B$3)+4*(ROW($B10)-ROW($B$3))) -> 323 | J10: =INDEX('Обработка исходного'!M:M,ROW($B$3)+4*(ROW($B10)-ROW($B$3))) -> 314 | K10: =INDEX('Обработка исходного'!N:N,ROW($B$3)+4*(ROW($B10)-ROW($B$3))) -> 294 | L10: =INDEX('Обработка исходного'!O:O,ROW($B$3)+4*(ROW($B10)-ROW($B$3))) -> - | M10: =INDEX('Обработка исходного'!P:P,ROW($B$3)+4*(ROW($B10)-ROW($B$3))) -> - | N10: =INDEX('Обработка исходного'!Q:Q,ROW($B$3)+4*(ROW($B10)-ROW($B$3))) -> - | O10: =INDEX('Обработка исходного'!R:R,ROW($B$3)+4*(ROW($B10)-ROW($B$3))) -> - | P10: =INDEX('Обработка исходного'!S:S,ROW($B$3)+4*(ROW($B10)-ROW($B$3))) -> -
A11: =INDEX('Обработка исходного'!B:B,ROW($B$3)+4*(ROW($B11)-ROW($B$3))) -> Сталь углеродистая | B11: =INDEX('Обработка исходного'!D:D,ROW($B$3)+4*(ROW($B11)-ROW($B$3))) -> 10 | C11: =IF(ISBLANK(INDEX('Обработка исходного'!E:E,ROW($B$3)+4*(ROW($B11)-ROW($B$3)))),"",INDEX('Обработка исходного'!E:E,ROW($B$3)+4*(ROW($B11)-ROW($B$3)))) -> Сортовая горячекатаная и кованая сталь толщиной или диаметром до 80 мм | D11: =INDEX('Обработка исходного'!G:G,ROW($B$3)+4*(ROW($B11)-ROW($B$3))) -> 333 | E11: =INDEX('Обработка исходного'!H:H,ROW($B$3)+4*(ROW($B11)-ROW($B$3))) -> 333 | F11: =INDEX('Обработка исходного'!I:I,ROW($B$3)+4*(ROW($B11)-ROW($B$3))) -> 333 | G11: =INDEX('Обработка исходного'!J:J,ROW($B$3)+4*(ROW($B11)-ROW($B$3))) -> 333 | H11: =INDEX('Обработка исходного'!K:K,ROW($B$3)+4*(ROW($B11)-ROW($B$3))) -> 333 | I11: =INDEX('Обработка исходного'!L:L,ROW($B$3)+4*(ROW($B11)-ROW($B$3))) -> 323 | J11: =INDEX('Обработка исходного'!M:M,ROW($B$3)+4*(ROW($B11)-ROW($B$3))) -> 314 | K11: =INDEX('Обработка исходного'!N:N,ROW($B$3)+4*(ROW($B11)-ROW($B$3))) -> 294 | L11: =INDEX('Обработка исходного'!O:O,ROW($B$3)+4*(ROW($B11)-ROW($B$3))) -> - | M11: =INDEX('Обработка исходного'!P:P,ROW($B$3)+4*(ROW($B11)-ROW($B$3))) -> - | N11: =INDEX('Обработка исходного'!Q:Q,ROW($B$3)+4*(ROW($B11)-ROW($B$3))) -> - | O11: =INDEX('Обработка исходного'!R:R,ROW($B$3)+4*(ROW($B11)-ROW($B$3))) -> - | P11: =INDEX('Обработка исходного'!S:S,ROW($B$3)+4*(ROW($B11)-ROW($B$3))) -> -
A12: =INDEX('Обработка исходного'!B:B,ROW($B$3)+4*(ROW($B12)-ROW($B$3))) -> Сталь углеродистая | B12: =INDEX('Обработка исходного'!D:D,ROW($B$3)+4*(ROW($B12)-ROW($B$3))) -> 15 | C12: =IF(ISBLANK(INDEX('Обработка исходного'!E:E,ROW($B$3)+4*(ROW($B12)-ROW($B$3)))),"",INDEX('Обработка исходного'!E:E,ROW($B$3)+4*(ROW($B12)-ROW($B$3)))) -> Сортовая горячекатаная сталь толщиной или диаметром до 80 мм | D12: =INDEX('Обработка исходного'!G:G,ROW($B$3)+4*(ROW($B12)-ROW($B$3))) -> 373 | E12: =INDEX('Обработка исходного'!H:H,ROW($B$3)+4*(ROW($B12)-ROW($B$3))) -> 373 | F12: =INDEX('Обработка исходного'!I:I,ROW($B$3)+4*(ROW($B12)-ROW($B$3))) -> 363 | G12: =INDEX('Обработка исходного'!J:J,ROW($B$3)+4*(ROW($B12)-ROW($B$3))) -> 353 | H12: =INDEX('Обработка исходного'!K:K,ROW($B$3)+4*(ROW($B12)-ROW($B$3))) -> 343 | I12: =INDEX('Обработка исходного'!L:L,ROW($B$3)+4*(ROW($B12)-ROW($B$3))) -> 333 | J12: =INDEX('Обработка исходного'!M:M,ROW($B$3)+4*(ROW($B12)-ROW($B$3))) -> 333 | K12: =INDEX('Обработка исходного'!N:N,ROW($B$3)+4*(ROW($B12)-ROW($B$3))) -> 333 | L12: =INDEX('Обработка исходного'!O:O,ROW($B$3)+4*(ROW($B12)-ROW($B$3))) -> - | M12: =INDEX('Обработка исходного'!P:P,ROW($B$3)+4*(ROW($B12)-ROW($B$3))) -> - | N12: =INDEX('Обработка исходного'!Q:Q,ROW($B$3)+4*(ROW($B12)-ROW($B$3))) -> - | O12: =INDEX('Обработка исходного'!R:R,ROW($B$3)+4*(ROW($B12)-ROW($B$3))) -> - | P12: =INDEX('Обработка исходного'!S:S,ROW($B$3)+4*(ROW($B12)-ROW($B$3))) -> -
A13: =INDEX('Обработка исходного'!B:B,ROW($B$3)+4*(ROW($B13)-ROW($B$3))) -> Сталь углеродистая | B13: =INDEX('Обработка исходного'!D:D,ROW($B$3)+4*(ROW($B13)-ROW($B$3))) -> 15 | C13: =IF(ISBLANK(INDEX('Обработка исходного'!E:E,ROW($B$3)+4*(ROW($B13)-ROW($B$3)))),"",INDEX('Обработка исходного'!E:E,ROW($B$3)+4*(ROW($B13)-ROW($B$3)))) -> Поковки диаметром до 300 мм, КП175* | D13: =INDEX('Обработка исходного'!G:G,ROW($B$3)+4*(ROW($B13)-ROW($B$3))) -> 355 | E13: =INDEX('Обработка исходного'!H:H,ROW($B$3)+4*(ROW($B13)-ROW($B$3))) -> 343 | F13: =INDEX('Обработка исходного'!I:I,ROW($B$3)+4*(ROW($B13)-ROW($B$3))) -> 333 | G13: =INDEX('Обработка исходного'!J:J,ROW($B$3)+4*(ROW($B13)-ROW($B$3))) -> 324 | H13: =INDEX('Обработка исходного'!K:K,ROW($B$3)+4*(ROW($B13)-ROW($B$3))) -> 314 | I13: =INDEX('Обработка исходного'!L:L,ROW($B$3)+4*(ROW($B13)-ROW($B$3))) -> 294 | J13: =INDEX('Обработка исходного'!M:M,ROW($B$3)+4*(ROW($B13)-ROW($B$3))) -> 294 | K13: =INDEX('Обработка исходного'!N:N,ROW($B$3)+4*(ROW($B13)-ROW($B$3))) -> 294 | L13: =INDEX('Обработка исходного'!O:O,ROW($B$3)+4*(ROW($B13)-ROW($B$3))) -> - | M13: =INDEX('Обработка исходного'!P:P,ROW($B$3)+4*(ROW($B13)-ROW($B$3))) -> - | N13: =INDEX('Обработка исходного'!Q:Q,ROW($B$3)+4*(ROW($B13)-ROW($B$3))) -> - | O13: =INDEX('Обработка исходного'!R:R,ROW($B$3)+4*(ROW($B13)-ROW($B$3))) -> - | P13: =INDEX('Обработка исходного'!S:S,ROW($B$3)+4*(ROW($B13)-ROW($B$3))) -> -
A14: =INDEX('Обработка исходного'!B:B,ROW($B$3)+4*(ROW($B14)-ROW($B$3))) -> Сталь углеродистая | B14: =INDEX('Обработка исходного'!D:D,ROW($B$3)+4*(ROW($B14)-ROW($B$3))) -> 15 | C14: =IF(ISBLANK(INDEX('Обработка исходного'!E:E,ROW($B$3)+4*(ROW($B14)-ROW($B$3)))),"",INDEX('Обработка исходного'!E:E,ROW($B$3)+4*(ROW($B14)-ROW($B$3)))) -> Поковки диаметром до 100 мм, КП195* | D14: =INDEX('Обработка исходного'!G:G,ROW($B$3)+4*(ROW($B14)-ROW($B$3))) -> 390 | E14: =INDEX('Обработка исходного'!H:H,ROW($B$3)+4*(ROW($B14)-ROW($B$3))) -> 383 | F14: =INDEX('Обработка исходного'!I:I,ROW($B$3)+4*(ROW($B14)-ROW($B$3))) -> 373 | G14: =INDEX('Обработка исходного'!J:J,ROW($B$3)+4*(ROW($B14)-ROW($B$3))) -> 363 | H14: =INDEX('Обработка исходного'!K:K,ROW($B$3)+4*(ROW($B14)-ROW($B$3))) -> 353 | I14: =INDEX('Обработка исходного'!L:L,ROW($B$3)+4*(ROW($B14)-ROW($B$3))) -> 343 | J14: =INDEX('Обработка исходного'!M:M,ROW($B$3)+4*(ROW($B14)-ROW($B$3))) -> 333 | K14: =INDEX('Обработка исходного'!N:N,ROW($B$3)+4*(ROW($B14)-ROW($B$3))) -> 324 | L14: =INDEX('Обработка исходного'!O:O,ROW($B$3)+4*(ROW($B14)-ROW($B$3))) -> - | M14: =INDEX('Обработка исходного'!P:P,ROW($B$3)+4*(ROW($B14)-ROW($B$3))) -> - | N14: =INDEX('Обработка исходного'!Q:Q,ROW($B$3)+4*(ROW($B14)-ROW($B$3))) -> - | O14: =INDEX('Обработка исходного'!R:R,ROW($B$3)+4*(ROW($B14)-ROW($B$3))) -> - | P14: =INDEX('Обработка исходного'!S:S,ROW($B$3)+4*(ROW($B14)-ROW($B$3))) -> -
... A359: =INDEX('Обработка исходного'!B:B,ROW($B$3)+4*(ROW($B359)-ROW($B$3))) -> Сплав на железоникелевой основе | B359: =INDEX('Обработка исходного'!D:D,ROW($B$3)+4*(ROW($B359)-ROW($B$3))) -> Сплав 0Х20Н46Б | C359: =IF(ISBLANK(INDEX('Обработка исходного'!E:E,ROW($B$3)+4*(ROW($B359)-ROW($B$3)))),"",INDEX('Обработка исходного'!E:E,ROW($B$3)+4*(ROW($B359)-ROW($B$3)))) -> Прутки круглого и квадратного сечения толщиной или диаметром от 30 до 170 мм | D359: =INDEX('Обработка исходного'!G:G,ROW($B$3)+4*(ROW($B359)-ROW($B$3))) -> 540 | E359: =INDEX('Обработка исходного'!H:H,ROW($B$3)+4*(ROW($B359)-ROW($B$3))) -> 530 | F359: =INDEX('Обработка исходного'!I:I,ROW($B$3)+4*(ROW($B359)-ROW($B$3))) -> 530 | G359: =INDEX('Обработка исходного'!J:J,ROW($B$3)+4*(ROW($B359)-ROW($B$3))) -> 510 | H359: =INDEX('Обработка исходного'!K:K,ROW($B$3)+4*(ROW($B359)-ROW($B$3))) -> 471 | I359: =INDEX('Обработка исходного'!L:L,ROW($B$3)+4*(ROW($B359)-ROW($B$3))) -> 461 | J359: =INDEX('Обработка исходного'!M:M,ROW($B$3)+4*(ROW($B359)-ROW($B$3))) -> 461 | K359: =INDEX('Обработка исходного'!N:N,ROW($B$3)+4*(ROW($B359)-ROW($B$3))) -> 461 | L359: =INDEX('Обработка исходного'!O:O,ROW($B$3)+4*(ROW($B359)-ROW($B$3))) -> 461 | M359: =INDEX('Обработка исходного'!P:P,ROW($B$3)+4*(ROW($B359)-ROW($B$3))) -> 461 | N359: =INDEX('Обработка исходного'!Q:Q,ROW($B$3)+4*(ROW($B359)-ROW($B$3))) -> 451 | O359: =INDEX('Обработка исходного'!R:R,ROW($B$3)+4*(ROW($B359)-ROW($B$3))) -> 441 | P359: =INDEX('Обработка исходного'!S:S,ROW($B$3)+4*(ROW($B359)-ROW($B$3))) -> 412

Sheet Rp0,2, МПа
A1: Класс материала | B1: Марка стали или сплава | C1: Сортамент | D1: Температура, К (°С)
D2: 20 | E2: 50 | F2: 100 | G2: 150 | H2: 200 | I2: 250 | J2: 300 | K2: 350 | L2: 400 | M2: 450 | N2: 500 | O2: 550 | P2: 600
A3: =INDEX('Обработка исходного'!B:B,ROW($B$3)+4*(ROW($B3)-ROW($B$3))) -> Сталь углеродистая | B3: =INDEX('Обработка исходного'!D:D,ROW($B$3)+4*(ROW($B3)-ROW($B$3))) -> Ст3сп5 | C3: =IF(ISBLANK(INDEX('Обработка исходного'!E:E,ROW($B$3)+4*(ROW($B3)-ROW($B$3)))),"",INDEX('Обработка исходного'!E:E,ROW($B$3)+4*(ROW($B3)-ROW($B$3)))) -> Горячекатаная сортовая фасонная и листовая сталь толщиной до 20 мм | D3: =INDEX('Обработка исходного'!G:G,ROW($B$3)+4*(ROW($B3)-ROW($B$3))+1) -> 245 | E3: =INDEX('Обработка исходного'!H:H,ROW($B$3)+4*(ROW($B3)-ROW($B$3))+1) -> 235 | F3: =INDEX('Обработка исходного'!I:I,ROW($B$3)+4*(ROW($B3)-ROW($B$3))+1) -> 235 | G3: =INDEX('Обработка исходного'!J:J,ROW($B$3)+4*(ROW($B3)-ROW($B$3))+1) -> 235 | H3: =INDEX('Обработка исходного'!K:K,ROW($B$3)+4*(ROW($B3)-ROW($B$3))+1) -> 235 | I3: =INDEX('Обработка исходного'!L:L,ROW($B$3)+4*(ROW($B3)-ROW($B$3))+1) -> 206 | J3: =INDEX('Обработка исходного'!M:M,ROW($B$3)+4*(ROW($B3)-ROW($B$3))+1) -> 186 | K3: =INDEX('Обработка исходного'!N:N,ROW($B$3)+4*(ROW($B3)-ROW($B$3))+1) -> - | L3: =INDEX('Обработка исходного'!O:O,ROW($B$3)+4*(ROW($B3)-ROW($B$3))+1) -> - | M3: =INDEX('Обработка исходного'!P:P,ROW($B$3)+4*(ROW($B3)-ROW($B$3))+1) -> - | N3: =INDEX('Обработка исходного'!Q:Q,ROW($B$3)+4*(ROW($B3)-ROW($B$3))+1) -> - | O3: =INDEX('Обработка исходного'!R:R,ROW($B$3)+4*(ROW($B3)-ROW($B$3))+1) -> - | P3: =INDEX('Обработка исходного'!S:S,ROW($B$3)+4*(ROW($B3)-ROW($B$3))+1) -> -
A4: =INDEX('Обработка исходного'!B:B,ROW($B$3)+4*(ROW($B4)-ROW($B$3))) -> Сталь углеродистая | B4: =INDEX('Обработка исходного'!D:D,ROW($B$3)+4*(ROW($B4)-ROW($B$3))) -> Ст3сп5 | C4: =IF(ISBLANK(INDEX('Обработка исходного'!E:E,ROW($B$3)+4*(ROW($B4)-ROW($B$3)))),"",INDEX('Обработка исходного'!E:E,ROW($B$3)+4*(ROW($B4)-ROW($B$3)))) -> Горячекатаная сортовая фасонная и листовая сталь толщиной от 20 до 100 мм | D4: =INDEX('Обработка исходного'!G:G,ROW($B$3)+4*(ROW($B4)-ROW($B$3))+1) -> 206 | E4: =INDEX('Обработка исходного'!H:H,ROW($B$3)+4*(ROW($B4)-ROW($B$3))+1) -> 196 | F4: =INDEX('Обработка исходного'!I:I,ROW($B$3)+4*(ROW($B4)-ROW($B$3))+1) -> 196 | G4: =INDEX('Обработка исходного'!J:J,ROW($B$3)+4*(ROW($B4)-ROW($B$3))+1) -> 196 | H4: =INDEX('Обработка исходного'!K:K,ROW($B$3)+4*(ROW($B4)-ROW($B$3))+1) -> 196 | I4: =INDEX('Обработка исходного'!L:L,ROW($B$3)+4*(ROW($B4)-ROW($B$3))+1) -> 177 | J4: =INDEX('Обработка исходного'!M:M,ROW($B$3)+4*(ROW($B4)-ROW($B$3))+1) -> 157 | K4: =INDEX('Обработка исходного'!N:N,ROW($B$3)+4*(ROW($B4)-ROW($B$3))+1) -> - | L4: =INDEX('Обработка исходного'!O:O,ROW($B$3)+4*(ROW($B4)-ROW($B$3))+1) -> - | M4: =INDEX('Обработка исходного'!P:P,ROW($B$3)+4*(ROW($B4)-ROW($B$3))+1) -> - | N4: =INDEX('Обработка исходного'!Q:Q,ROW($B$3)+4*(ROW($B4)-ROW($B$3))+1) -> - | O4: =INDEX('Обработка исходного'!R:R,ROW($B$3)+4*(ROW($B4)-ROW($B$3))+1) -> - | P4: =INDEX('Обработка исходного'!S:S,ROW($B$3)+4*(ROW($B4)-ROW($B$3))+1) -> -
A5: =INDEX('Обработка исходного'!B:B,ROW($B$3)+4*(ROW($B5)-ROW($B$3))) -> Сталь углеродистая | B5: =INDEX('Обработка исходного'!D:D,ROW($B$3)+4*(ROW($B5)-ROW($B$3))) -> Ст3сп5 | C5: =IF(ISBLANK(INDEX('Обработка исходного'!E:E,ROW($B$3)+4*(ROW($B5)-ROW($B$3)))),"",INDEX('Обработка исходного'!E:E,ROW($B$3)+4*(ROW($B5)-ROW($B$3)))) -> Горячекатаная сортовая фасонная и листовая сталь толщиной более 100 мм | D5: =INDEX('Обработка исходного'!G:G,ROW($B$3)+4*(ROW($B5)-ROW($B$3))+1) -> 206 | E5: =INDEX('Обработка исходного'!H:H,ROW($B$3)+4*(ROW($B5)-ROW($B$3))+1) -> 196 | F5: =INDEX('Обработка исходного'!I:I,ROW($B$3)+4*(ROW($B5)-ROW($B$3))+1) -> 196 | G5: =INDEX('Обработка исходного'!J:J,ROW($B$3)+4*(ROW($B5)-ROW($B$3))+1) -> 196 | H5: =INDEX('Обработка исходного'!K:K,ROW($B$3)+4*(ROW($B5)-ROW($B$3))+1) -> 196 | I5: =INDEX('Обработка исходного'!L:L,ROW($B$3)+4*(ROW($B5)-ROW($B$3))+1) -> 177 | J5: =INDEX('Обработка исходного'!M:M,ROW($B$3)+4*(ROW($B5)-ROW($B$3))+1) -> 157 | K5: =INDEX('Обработка исходного'!N:N,ROW($B$3)+4*(ROW($B5)-ROW($B$3))+1) -> - | L5: =INDEX('Обработка исходного'!O:O,ROW($B$3)+4*(ROW($B5)-ROW($B$3))+1) -> - | M5: =INDEX('Обработка исходного'!P:P,ROW($B$3)+4*(ROW($B5)-ROW($B$3))+1) -> - | N5: =INDEX('Обработка исходного'!Q:Q,ROW($B$3)+4*(ROW($B5)-ROW($B$3))+1) -> - | O5: =INDEX('Обработка исходного'!R:R,ROW($B$3)+4*(ROW($B5)-ROW($B$3))+1) -> - | P5: =INDEX('Обработка исходного'!S:S,ROW($B$3)+4*(ROW($B5)-ROW($B$3))+1) -> -
A6: =INDEX('Обработка исходного'!B:B,ROW($B$3)+4*(ROW($B6)-ROW($B$3))) -> Сталь углеродистая | B6: =INDEX('Обработка исходного'!D:D,ROW($B$3)+4*(ROW($B6)-ROW($B$3))) -> Ст3сп5 | C6: =IF(ISBLANK(INDEX('Обработка исходного'!E:E,ROW($B$3)+4*(ROW($B6)-ROW($B$3)))),"",INDEX('Обработка исходного'!E:E,ROW($B$3)+4*(ROW($B6)-ROW($B$3)))) -> Трубы | D6: =INDEX('Обработка исходного'!G:G,ROW($B$3)+4*(ROW($B6)-ROW($B$3))+1) -> 206 | E6: =INDEX('Обработка исходного'!H:H,ROW($B$3)+4*(ROW($B6)-ROW($B$3))+1) -> 196 | F6: =INDEX('Обработка исходного'!I:I,ROW($B$3)+4*(ROW($B6)-ROW($B$3))+1) -> 196 | G6: =INDEX('Обработка исходного'!J:J,ROW($B$3)+4*(ROW($B6)-ROW($B$3))+1) -> 196 | H6: =INDEX('Обработка исходного'!K:K,ROW($B$3)+4*(ROW($B6)-ROW($B$3))+1) -> 196 | I6: =INDEX('Обработка исходного'!L:L,ROW($B$3)+4*(ROW($B6)-ROW($B$3))+1) -> 177 | J6: =INDEX('Обработка исходного'!M:M,ROW($B$3)+4*(ROW($B6)-ROW($B$3))+1) -> 157 | K6: =INDEX('Обработка исходного'!N:N,ROW($B$3)+4*(ROW($B6)-ROW($B$3))+1) -> - | L6: =INDEX('Обработка исходного'!O:O,ROW($B$3)+4*(ROW($B6)-ROW($B$3))+1) -> - | M6: =INDEX('Обработка исходного'!P:P,ROW($B$3)+4*(ROW($B6)-ROW($B$3))+1) -> - | N6: =INDEX('Обработка исходного'!Q:Q,ROW($B$3)+4*(ROW($B6)-ROW($B$3))+1) -> - | O6: =INDEX('Обработка исходного'!R:R,ROW($B$3)+4*(ROW($B6)-ROW($B$3))+1) -> - | P6: =INDEX('Обработка исходного'!S:S,ROW($B$3)+4*(ROW($B6)-ROW($B$3))+1) -> -
A7: =INDEX('Обработка исходного'!B:B,ROW($B$3)+4*(ROW($B7)-ROW($B$3))) -> Сталь углеродистая | B7: =INDEX('Обработка исходного'!D:D,ROW($B$3)+4*(ROW($B7)-ROW($B$3))) -> Ст3сп5 | C7: =IF(ISBLANK(INDEX('Обработка исходного'!E:E,ROW($B$3)+4*(ROW($B7)-ROW($B$3)))),"",INDEX('Обработка исходного'!E:E,ROW($B$3)+4*(ROW($B7)-ROW($B$3)))) -> Поковки диаметром или толщиной до 300 мм, КП175* | D7: =INDEX('Обработка исходного'!G:G,ROW($B$3)+4*(ROW($B7)-ROW($B$3))+1) -> 175 | E7: =INDEX('Обработка исходного'!H:H,ROW($B$3)+4*(ROW($B7)-ROW($B$3))+1) -> 167 | F7: =INDEX('Обработка исходного'!I:I,ROW($B$3)+4*(ROW($B7)-ROW($B$3))+1) -> 167 | G7: =INDEX('Обработка исходного'!J:J,ROW($B$3)+4*(ROW($B7)-ROW($B$3))+1) -> 167 | H7: =INDEX('Обработка исходного'!K:K,ROW($B$3)+4*(ROW($B7)-ROW($B$3))+1) -> 157 | I7: =INDEX('Обработка исходного'!L:L,ROW($B$3)+4*(ROW($B7)-ROW($B$3))+1) -> 147 | J7: =INDEX('Обработка исходного'!M:M,ROW($B$3)+4*(ROW($B7)-ROW($B$3))+1) -> 137 | K7: =INDEX('Обработка исходного'!N:N,ROW($B$3)+4*(ROW($B7)-ROW($B$3))+1) -> - | L7: =INDEX('Обработка исходного'!O:O,ROW($B$3)+4*(ROW($B7)-ROW($B$3))+1) -> - | M7: =INDEX('Обработка исходного'!P:P,ROW($B$3)+4*(ROW($B7)-ROW($B$3))+1) -> - | N7: =INDEX('Обработка исходного'!Q:Q,ROW($B$3)+4*(ROW($B7)-ROW($B$3))+1) -> - | O7: =INDEX('Обработка исходного'!R:R,ROW($B$3)+4*(ROW($B7)-ROW($B$3))+1) -> - | P7: =INDEX('Обработка исходного'!S:S,ROW($B$3)+4*(ROW($B7)-ROW($B$3))+1) -> -
A8: =INDEX('Обработка исходного'!B:B,ROW($B$3)+4*(ROW($B8)-ROW($B$3))) -> Сталь углеродистая | B8: =INDEX('Обработка исходного'!D:D,ROW($B$3)+4*(ROW($B8)-ROW($B$3))) -> Ст3сп5 | C8: =IF(ISBLANK(INDEX('Обработка исходного'!E:E,ROW($B$3)+4*(ROW($B8)-ROW($B$3)))),"",INDEX('Обработка исходного'!E:E,ROW($B$3)+4*(ROW($B8)-ROW($B$3)))) -> Поковки диаметром или толщиной до 300 мм, КП195* | D8: =INDEX('Обработка исходного'!G:G,ROW($B$3)+4*(ROW($B8)-ROW($B$3))+1) -> 195 | E8: =INDEX('Обработка исходного'!H:H,ROW($B$3)+4*(ROW($B8)-ROW($B$3))+1) -> 195 | F8: =INDEX('Обработка исходного'!I:I,ROW($B$3)+4*(ROW($B8)-ROW($B$3))+1) -> 195 | G8: =INDEX('Обработка исходного'!J:J,ROW($B$3)+4*(ROW($B8)-ROW($B$3))+1) -> 195 | H8: =INDEX('Обработка исходного'!K:K,ROW($B$3)+4*(ROW($B8)-ROW($B$3))+1) -> 177 | I8: =INDEX('Обработка исходного'!L:L,ROW($B$3)+4*(ROW($B8)-ROW($B$3))+1) -> 167 | J8: =INDEX('Обработка исходного'!M:M,ROW($B$3)+4*(ROW($B8)-ROW($B$3))+1) -> 147 | K8: =INDEX('Обработка исходного'!N:N,ROW($B$3)+4*(ROW($B8)-ROW($B$3))+1) -> - | L8: =INDEX('Обработка исходного'!O:O,ROW($B$3)+4*(ROW($B8)-ROW($B$3))+1) -> - | M8: =INDEX('Обработка исходного'!P:P,ROW($B$3)+4*(ROW($B8)-ROW($B$3))+1) -> - | N8: =INDEX('Обработка исходного'!Q:Q,ROW($B$3)+4*(ROW($B8)-ROW($B$3))+1) -> - | O8: =INDEX('Обработка исходного'!R:R,ROW($B$3)+4*(ROW($B8)-ROW($B$3))+1) -> - | P8: =INDEX('Обработка исходного'!S:S,ROW($B$3)+4*(ROW($B8)-ROW($B$3))+1) -> -
A9: =INDEX('Обработка исходного'!B:B,ROW($B$3)+4*(ROW($B9)-ROW($B$3))) -> Сталь углеродистая | B9: =INDEX('Обработка исходного'!D:D,ROW($B$3)+4*(ROW($B9)-ROW($B$3))) -> Ст3сп5 | C9: =IF(ISBLANK(INDEX('Обработка исходного'!E:E,ROW($B$3)+4*(ROW($B9)-ROW($B$3)))),"",INDEX('Обработка исходного'!E:E,ROW($B$3)+4*(ROW($B9)-ROW($B$3)))) -> Поковки диаметром или толщиной до 50 мм, КП215* | D9: =INDEX('Обработка исходного'!G:G,ROW($B$3)+4*(ROW($B9)-ROW($B$3))+1) -> 215 | E9: =INDEX('Обработка исходного'!H:H,ROW($B$3)+4*(ROW($B9)-ROW($B$3))+1) -> 206 | F9: =INDEX('Обработка исходного'!I:I,ROW($B$3)+4*(ROW($B9)-ROW($B$3))+1) -> 206 | G9: =INDEX('Обработка исходного'!J:J,ROW($B$3)+4*(ROW($B9)-ROW($B$3))+1) -> 206 | H9: =INDEX('Обработка исходного'!K:K,ROW($B$3)+4*(ROW($B9)-ROW($B$3))+1) -> 196 | I9: =INDEX('Обработка исходного'!L:L,ROW($B$3)+4*(ROW($B9)-ROW($B$3))+1) -> 196 | J9: =INDEX('Обработка исходного'!M:M,ROW($B$3)+4*(ROW($B9)-ROW($B$3))+1) -> 167 | K9: =INDEX('Обработка исходного'!N:N,ROW($B$3)+4*(ROW($B9)-ROW($B$3))+1) -> - | L9: =INDEX('Обработка исходного'!O:O,ROW($B$3)+4*(ROW($B9)-ROW($B$3))+1) -> - | M9: =INDEX('Обработка исходного'!P:P,ROW($B$3)+4*(ROW($B9)-ROW($B$3))+1) -> - | N9: =INDEX('Обработка исходного'!Q:Q,ROW($B$3)+4*(ROW($B9)-ROW($B$3))+1) -> - | O9: =INDEX('Обработка исходного'!R:R,ROW($B$3)+4*(ROW($B9)-ROW($B$3))+1) -> - | P9: =INDEX('Обработка исходного'!S:S,ROW($B$3)+4*(ROW($B9)-ROW($B$3))+1) -> -
A10: =INDEX('Обработка исходного'!B:B,ROW($B$3)+4*(ROW($B10)-ROW($B$3))) -> Сталь углеродистая | B10: =INDEX('Обработка исходного'!D:D,ROW($B$3)+4*(ROW($B10)-ROW($B$3))) -> 10 | C10: =IF(ISBLANK(INDEX('Обработка исходного'!E:E,ROW($B$3)+4*(ROW($B10)-ROW($B$3)))),"",INDEX('Обработка исходного'!E:E,ROW($B$3)+4*(ROW($B10)-ROW($B$3)))) -> Трубы холодно- и теплодеформированные бесшовные | D10: =INDEX('Обработка исходного'!G:G,ROW($B$3)+4*(ROW($B10)-ROW($B$3))+1) -> 206 | E10: =INDEX('Обработка исходного'!H:H,ROW($B$3)+4*(ROW($B10)-ROW($B$3))+1) -> 196 | F10: =INDEX('Обработка исходного'!I:I,ROW($B$3)+4*(ROW($B10)-ROW($B$3))+1) -> 195 | G10: =INDEX('Обработка исходного'!J:J,ROW($B$3)+4*(ROW($B10)-ROW($B$3))+1) -> 181 | H10: =INDEX('Обработка исходного'!K:K,ROW($B$3)+4*(ROW($B10)-ROW($B$3))+1) -> 176 | I10: =INDEX('Обработка исходного'!L:L,ROW($B$3)+4*(ROW($B10)-ROW($B$3))+1) -> 157 | J10: =INDEX('Обработка исходного'!M:M,ROW($B$3)+4*(ROW($B10)-ROW($B$3))+1) -> 137 | K10: =INDEX('Обработка исходного'!N:N,ROW($B$3)+4*(ROW($B10)-ROW($B$3))+1) -> 118 | L10: =INDEX('Обработка исходного'!O:O,ROW($B$3)+4*(ROW($B10)-ROW($B$3))+1) -> - | M10: =INDEX('Обработка исходного'!P:P,ROW($B$3)+4*(ROW($B10)-ROW($B$3))+1) -> - | N10: =INDEX('Обработка исходного'!Q:Q,ROW($B$3)+4*(ROW($B10)-ROW($B$3))+1) -> - | O10: =INDEX('Обработка исходного'!R:R,ROW($B$3)+4*(ROW($B10)-ROW($B$3))+1) -> - | P10: =INDEX('Обработка исходного'!S:S,ROW($B$3)+4*(ROW($B10)-ROW($B$3))+1) -> -
A11: =INDEX('Обработка исходного'!B:B,ROW($B$3)+4*(ROW($B11)-ROW($B$3))) -> Сталь углеродистая | B11: =INDEX('Обработка исходного'!D:D,ROW($B$3)+4*(ROW($B11)-ROW($B$3))) -> 10 | C11: =IF(ISBLANK(INDEX('Обработка исходного'!E:E,ROW($B$3)+4*(ROW($B11)-ROW($B$3)))),"",INDEX('Обработка исходного'!E:E,ROW($B$3)+4*(ROW($B11)-ROW($B$3)))) -> Сортовая горячекатаная и кованая сталь толщиной или диаметром до 80 мм | D11: =INDEX('Обработка исходного'!G:G,ROW($B$3)+4*(ROW($B11)-ROW($B$3))+1) -> 186 | E11: =INDEX('Обработка исходного'!H:H,ROW($B$3)+4*(ROW($B11)-ROW($B$3))+1) -> 186 | F11: =INDEX('Обработка исходного'!I:I,ROW($B$3)+4*(ROW($B11)-ROW($B$3))+1) -> 186 | G11: =INDEX('Обработка исходного'!J:J,ROW($B$3)+4*(ROW($B11)-ROW($B$3))+1) -> 177 | H11: =INDEX('Обработка исходного'!K:K,ROW($B$3)+4*(ROW($B11)-ROW($B$3))+1) -> 177 | I11: =INDEX('Обработка исходного'!L:L,ROW($B$3)+4*(ROW($B11)-ROW($B$3))+1) -> 157 | J11: =INDEX('Обработка исходного'!M:M,ROW($B$3)+4*(ROW($B11)-ROW($B$3))+1) -> 137 | K11: =INDEX('Обработка исходного'!N:N,ROW($B$3)+4*(ROW($B11)-ROW($B$3))+1) -> 118 | L11: =INDEX('Обработка исходного'!O:O,ROW($B$3)+4*(ROW($B11)-ROW($B$3))+1) -> - | M11: =INDEX('Обработка исходного'!P:P,ROW($B$3)+4*(ROW($B11)-ROW($B$3))+1) -> - | N11: =INDEX('Обработка исходного'!Q:Q,ROW($B$3)+4*(ROW($B11)-ROW($B$3))+1) -> - | O11: =INDEX('Обработка исходного'!R:R,ROW($B$3)+4*(ROW($B11)-ROW($B$3))+1) -> - | P11: =INDEX('Обработка исходного'!S:S,ROW($B$3)+4*(ROW($B11)-ROW($B$3))+1) -> -
A12: =INDEX('Обработка исходного'!B:B,ROW($B$3)+4*(ROW($B12)-ROW($B$3))) -> Сталь углеродистая | B12: =INDEX('Обработка исходного'!D:D,ROW($B$3)+4*(ROW($B12)-ROW($B$3))) -> 15 | C12: =IF(ISBLANK(INDEX('Обработка исходного'!E:E,ROW($B$3)+4*(ROW($B12)-ROW($B$3)))),"",INDEX('Обработка исходного'!E:E,ROW($B$3)+4*(ROW($B12)-ROW($B$3)))) -> Сортовая горячекатаная сталь толщиной или диаметром до 80 мм | D12: =INDEX('Обработка исходного'!G:G,ROW($B$3)+4*(ROW($B12)-ROW($B$3))+1) -> 226 | E12: =INDEX('Обработка исходного'!H:H,ROW($B$3)+4*(ROW($B12)-ROW($B$3))+1) -> 216 | F12: =INDEX('Обработка исходного'!I:I,ROW($B$3)+4*(ROW($B12)-ROW($B$3))+1) -> 216 | G12: =INDEX('Обработка исходного'!J:J,ROW($B$3)+4*(ROW($B12)-ROW($B$3))+1) -> 196 | H12: =INDEX('Обработка исходного'!K:K,ROW($B$3)+4*(ROW($B12)-ROW($B$3))+1) -> 196 | I12: =INDEX('Обработка исходного'!L:L,ROW($B$3)+4*(ROW($B12)-ROW($B$3))+1) -> 196 | J12: =INDEX('Обработка исходного'!M:M,ROW($B$3)+4*(ROW($B12)-ROW($B$3))+1) -> 196 | K12: =INDEX('Обработка исходного'!N:N,ROW($B$3)+4*(ROW($B12)-ROW($B$3))+1) -> 196 | L12: =INDEX('Обработка исходного'!O:O,ROW($B$3)+4*(ROW($B12)-ROW($B$3))+1) -> - | M12: =INDEX('Обработка исходного'!P:P,ROW($B$3)+4*(ROW($B12)-ROW($B$3))+1) -> - | N12: =INDEX('Обработка исходного'!Q:Q,ROW($B$3)+4*(ROW($B12)-ROW($B$3))+1) -> - | O12: =INDEX('Обработка исходного'!R:R,ROW($B$3)+4*(ROW($B12)-ROW($B$3))+1) -> - | P12: =INDEX('Обработка исходного'!S:S,ROW($B$3)+4*(ROW($B12)-ROW($B$3))+1) -> -
A13: =INDEX('Обработка исходного'!B:B,ROW($B$3)+4*(ROW($B13)-ROW($B$3))) -> Сталь углеродистая | B13: =INDEX('Обработка исходного'!D:D,ROW($B$3)+4*(ROW($B13)-ROW($B$3))) -> 15 | C13: =IF(ISBLANK(INDEX('Обработка исходного'!E:E,ROW($B$3)+4*(ROW($B13)-ROW($B$3)))),"",INDEX('Обработка исходного'!E:E,ROW($B$3)+4*(ROW($B13)-ROW($B$3)))) -> Поковки диаметром до 300 мм, КП175* | D13: =INDEX('Обработка исходного'!G:G,ROW($B$3)+4*(ROW($B13)-ROW($B$3))+1) -> 175 | E13: =INDEX('Обработка исходного'!H:H,ROW($B$3)+4*(ROW($B13)-ROW($B$3))+1) -> 167 | F13: =INDEX('Обработка исходного'!I:I,ROW($B$3)+4*(ROW($B13)-ROW($B$3))+1) -> 157 | G13: =INDEX('Обработка исходного'!J:J,ROW($B$3)+4*(ROW($B13)-ROW($B$3))+1) -> 147 | H13: =INDEX('Обработка исходного'!K:K,ROW($B$3)+4*(ROW($B13)-ROW($B$3))+1) -> 147 | I13: =INDEX('Обработка исходного'!L:L,ROW($B$3)+4*(ROW($B13)-ROW($B$3))+1) -> 128 | J13: =INDEX('Обработка исходного'!M:M,ROW($B$3)+4*(ROW($B13)-ROW($B$3))+1) -> 118 | K13: =INDEX('Обработка исходного'!N:N,ROW($B$3)+4*(ROW($B13)-ROW($B$3))+1) -> 118 | L13: =INDEX('Обработка исходного'!O:O,ROW($B$3)+4*(ROW($B13)-ROW($B$3))+1) -> - | M13: =INDEX('Обработка исходного'!P:P,ROW($B$3)+4*(ROW($B13)-ROW($B$3))+1) -> - | N13: =INDEX('Обработка исходного'!Q:Q,ROW($B$3)+4*(ROW($B13)-ROW($B$3))+1) -> - | O13: =INDEX('Обработка исходного'!R:R,ROW($B$3)+4*(ROW($B13)-ROW($B$3))+1) -> - | P13: =INDEX('Обработка исходного'!S:S,ROW($B$3)+4*(ROW($B13)-ROW($B$3))+1) -> -
A14: =INDEX('Обработка исходного'!B:B,ROW($B$3)+4*(ROW($B14)-ROW($B$3))) -> Сталь углеродистая | B14: =INDEX('Обработка исходного'!D:D,ROW($B$3)+4*(ROW($B14)-ROW($B$3))) -> 15 | C14: =IF(ISBLANK(INDEX('Обработка исходного'!E:E,ROW($B$3)+4*(ROW($B14)-ROW($B$3)))),"",INDEX('Обработка исходного'!E:E,ROW($B$3)+4*(ROW($B14)-ROW($B$3)))) -> Поковки диаметром до 100 мм, КП195* | D14: =INDEX('Обработка исходного'!G:G,ROW($B$3)+4*(ROW($B14)-ROW($B$3))+1) -> 195 | E14: =INDEX('Обработка исходного'!H:H,ROW($B$3)+4*(ROW($B14)-ROW($B$3))+1) -> 195 | F14: =INDEX('Обработка исходного'!I:I,ROW($B$3)+4*(ROW($B14)-ROW($B$3))+1) -> 177 | G14: =INDEX('Обработка исходного'!J:J,ROW($B$3)+4*(ROW($B14)-ROW($B$3))+1) -> 167 | H14: =INDEX('Обработка исходного'!K:K,ROW($B$3)+4*(ROW($B14)-ROW($B$3))+1) -> 167 | I14: =INDEX('Обработка исходного'!L:L,ROW($B$3)+4*(ROW($B14)-ROW($B$3))+1) -> 147 | J14: =INDEX('Обработка исходного'!M:M,ROW($B$3)+4*(ROW($B14)-ROW($B$3))+1) -> 128 | K14: =INDEX('Обработка исходного'!N:N,ROW($B$3)+4*(ROW($B14)-ROW($B$3))+1) -> 128 | L14: =INDEX('Обработка исходного'!O:O,ROW($B$3)+4*(ROW($B14)-ROW($B$3))+1) -> - | M14: =INDEX('Обработка исходного'!P:P,ROW($B$3)+4*(ROW($B14)-ROW($B$3))+1) -> - | N14: =INDEX('Обработка исходного'!Q:Q,ROW($B$3)+4*(ROW($B14)-ROW($B$3))+1) -> - | O14: =INDEX('Обработка исходного'!R:R,ROW($B$3)+4*(ROW($B14)-ROW($B$3))+1) -> - | P14: =INDEX('Обработка исходного'!S:S,ROW($B$3)+4*(ROW($B14)-ROW($B$3))+1) -> -
